Exception:
Traceback (most recent call last):
  File "/webapps/shellac/env/lib/python3.4/site-packages/pip/basecommand.py", line 122, in main
    status = self.run(options, args)
  File "/webapps/shellac/env/lib/python3.4/site-packages/pip/commands/install.py", line 257, in run
    InstallRequirement.from_line(name, None))
  File "/webapps/shellac/env/lib/python3.4/site-packages/pip/req.py", line 172, in from_line
    return cls(req, comes_from, url=url, prereleases=prereleases)
  File "/webapps/shellac/env/lib/python3.4/site-packages/pip/req.py", line 70, in __init__
    req = pkg_resources.Requirement.parse(req)
  File "/webapps/shellac/env/lib/python3.4/site-packages/pip/_vendor/pkg_resources.py", line 2606, in parse
    reqs = list(parse_requirements(s))
  File "/webapps/shellac/env/lib/python3.4/site-packages/pip/_vendor/pkg_resources.py", line 2544, in parse_requirements
    line, p, specs = scan_list(VERSION,LINE_END,line,p,(1,2),"version spec")
  File "/webapps/shellac/env/lib/python3.4/site-packages/pip/_vendor/pkg_resources.py", line 2512, in scan_list
    raise ValueError("Expected "+item_name+" in",line,"at",line[p:])
ValueError: ('Expected version spec in', 'django=1.6.5', 'at', '=1.6.5')
